[2021-02-01 03:31:07 +0000] [235] [INFO] Starting gunicorn 20.0.4
[2021-02-01 03:31:07 +0000] [235] [INFO] Listening at: http://0.0.0.0:8080 (235)
[2021-02-01 03:31:07 +0000] [235] [INFO] Using worker: gevent
[2021-02-01 03:31:07 +0000] [237] [INFO] Booting worker with pid: 237
[2021-02-01 03:31:07 +0000] [238] [INFO] Booting worker with pid: 238
[2021-02-01 03:31:07 +0000] [239] [INFO] Booting worker with pid: 239
[2021-02-01 03:31:07 +0000] [240] [INFO] Booting worker with pid: 240
[2021-02-01 03:31:17,415] ERROR in app: Exception on / [GET]
Traceback (most recent call last):
  File "/opt/virtualenvs/python3/lib/python3.8/site-packages/flask/app.py", line 2447, in wsgi_app
    response = self.full_dispatch_request()
  File "/opt/virtualenvs/python3/lib/python3.8/site-packages/flask/app.py", line 1952, in full_dispatch_request
    rv = self.handle_user_exception(e)
  File "/opt/virtualenvs/python3/lib/python3.8/site-packages/flask/app.py", line 1821, in handle_user_exception
    reraise(exc_type, exc_value, tb)
  File "/opt/virtualenvs/python3/lib/python3.8/site-packages/flask/_compat.py", line 39, in reraise
    raise value
  File "/opt/virtualenvs/python3/lib/python3.8/site-packages/flask/app.py", line 1950, in full_dispatch_request
    rv = self.dispatch_request()
  File "/opt/virtualenvs/python3/lib/python3.8/site-packages/flask/app.py", line 1936, in dispatch_request
    return self.view_functions[rule.endpoint](**req.view_args)
  File "/home/runner/ben-ben-spider/app.py", line 76, in main
    return render_template('zhuye.html', v=v, b=b.all(), form=form)
  File "/opt/virtualenvs/python3/lib/python3.8/site-packages/flask/templating.py", line 137, in render_template
    return _render(
  File "/opt/virtualenvs/python3/lib/python3.8/site-packages/flask/templating.py", line 120, in _render
    rv = template.render(context)
  File "/opt/virtualenvs/python3/lib/python3.8/site-packages/jinja2/environment.py", line 1090, in render
    self.environment.handle_exception()
  File "/opt/virtualenvs/python3/lib/python3.8/site-packages/jinja2/environment.py", line 832, in handle_exception
    reraise(*rewrite_traceback_stack(source=source))
  File "/opt/virtualenvs/python3/lib/python3.8/site-packages/jinja2/_compat.py", line 28, in reraise
    raise value.with_traceback(tb)
  File "/home/runner/ben-ben-spider/templates/zhuye.html", line 2, in top-level template code
    {% from 'bootstrap/form.html' import render_form_row,render_field %}
  File "/opt/virtualenvs/python3/lib/python3.8/site-packages/flask/templating.py", line 60, in get_source
    return self._get_source_fast(environment, template)
  File "/opt/virtualenvs/python3/lib/python3.8/site-packages/flask/templating.py", line 89, in _get_source_fast
    raise TemplateNotFound(template)
jinja2.exceptions.TemplateNotFound: bootstrap/form.html
[2021-02-01 03:31:17,555] ERROR in app: Exception on / [GET]
Traceback (most recent call last):
  File "/opt/virtualenvs/python3/lib/python3.8/site-packages/flask/app.py", line 2447, in wsgi_app
    response = self.full_dispatch_request()
  File "/opt/virtualenvs/python3/lib/python3.8/site-packages/flask/app.py", line 1952, in full_dispatch_request
    rv = self.handle_user_exception(e)
  File "/opt/virtualenvs/python3/lib/python3.8/site-packages/flask/app.py", line 1821, in handle_user_exception
    reraise(exc_type, exc_value, tb)
  File "/opt/virtualenvs/python3/lib/python3.8/site-packages/flask/_compat.py", line 39, in reraise
    raise value
  File "/opt/virtualenvs/python3/lib/python3.8/site-packages/flask/app.py", line 1950, in full_dispatch_request
    rv = self.dispatch_request()
  File "/opt/virtualenvs/python3/lib/python3.8/site-packages/flask/app.py", line 1936, in dispatch_request
    return self.view_functions[rule.endpoint](**req.view_args)
  File "/home/runner/ben-ben-spider/app.py", line 76, in main
    return render_template('zhuye.html', v=v, b=b.all(), form=form)
  File "/opt/virtualenvs/python3/lib/python3.8/site-packages/flask/templating.py", line 137, in render_template
    return _render(
  File "/opt/virtualenvs/python3/lib/python3.8/site-packages/flask/templating.py", line 120, in _render
    rv = template.render(context)
  File "/opt/virtualenvs/python3/lib/python3.8/site-packages/jinja2/environment.py", line 1090, in render
    self.environment.handle_exception()
  File "/opt/virtualenvs/python3/lib/python3.8/site-packages/jinja2/environment.py", line 832, in handle_exception
    reraise(*rewrite_traceback_stack(source=source))
  File "/opt/virtualenvs/python3/lib/python3.8/site-packages/jinja2/_compat.py", line 28, in reraise
    raise value.with_traceback(tb)
  File "/home/runner/ben-ben-spider/templates/zhuye.html", line 2, in top-level template code
    {% from 'bootstrap/form.html' import render_form_row,render_field %}
  File "/opt/virtualenvs/python3/lib/python3.8/site-packages/flask/templating.py", line 60, in get_source
    return self._get_source_fast(environment, template)
  File "/opt/virtualenvs/python3/lib/python3.8/site-packages/flask/templating.py", line 89, in _get_source_fast
    raise TemplateNotFound(template)
jinja2.exceptions.TemplateNotFound: bootstrap/form.html
[2021-02-01 03:31:19,529] ERROR in app: Exception on / [GET]
Traceback (most recent call last):
  File "/opt/virtualenvs/python3/lib/python3.8/site-packages/flask/app.py", line 2447, in wsgi_app
    response = self.full_dispatch_request()
  File "/opt/virtualenvs/python3/lib/python3.8/site-packages/flask/app.py", line 1952, in full_dispatch_request
    rv = self.handle_user_exception(e)
  File "/opt/virtualenvs/python3/lib/python3.8/site-packages/flask/app.py", line 1821, in handle_user_exception
    reraise(exc_type, exc_value, tb)
  File "/opt/virtualenvs/python3/lib/python3.8/site-packages/flask/_compat.py", line 39, in reraise
    raise value
  File "/opt/virtualenvs/python3/lib/python3.8/site-packages/flask/app.py", line 1950, in full_dispatch_request
    rv = self.dispatch_request()
  File "/opt/virtualenvs/python3/lib/python3.8/site-packages/flask/app.py", line 1936, in dispatch_request
    return self.view_functions[rule.endpoint](**req.view_args)
  File "/home/runner/ben-ben-spider/app.py", line 76, in main
    return render_template('zhuye.html', v=v, b=b.all(), form=form)
  File "/opt/virtualenvs/python3/lib/python3.8/site-packages/flask/templating.py", line 137, in render_template
    return _render(
  File "/opt/virtualenvs/python3/lib/python3.8/site-packages/flask/templating.py", line 120, in _render
    rv = template.render(context)
  File "/opt/virtualenvs/python3/lib/python3.8/site-packages/jinja2/environment.py", line 1090, in render
    self.environment.handle_exception()
  File "/opt/virtualenvs/python3/lib/python3.8/site-packages/jinja2/environment.py", line 832, in handle_exception
    reraise(*rewrite_traceback_stack(source=source))
  File "/opt/virtualenvs/python3/lib/python3.8/site-packages/jinja2/_compat.py", line 28, in reraise
    raise value.with_traceback(tb)
  File "/home/runner/ben-ben-spider/templates/zhuye.html", line 2, in top-level template code
    {% from 'bootstrap/form.html' import render_form_row,render_field %}
  File "/opt/virtualenvs/python3/lib/python3.8/site-packages/flask/templating.py", line 60, in get_source
    return self._get_source_fast(environment, template)
  File "/opt/virtualenvs/python3/lib/python3.8/site-packages/flask/templating.py", line 89, in _get_source_fast
    raise TemplateNotFound(template)
jinja2.exceptions.TemplateNotFound: bootstrap/form.html
[2021-02-01 03:31:21,012] ERROR in app: Exception on / [GET]
Traceback (most recent call last):
  File "/opt/virtualenvs/python3/lib/python3.8/site-packages/flask/app.py", line 2447, in wsgi_app
    response = self.full_dispatch_request()
  File "/opt/virtualenvs/python3/lib/python3.8/site-packages/flask/app.py", line 1952, in full_dispatch_request
    rv = self.handle_user_exception(e)
  File "/opt/virtualenvs/python3/lib/python3.8/site-packages/flask/app.py", line 1821, in handle_user_exception
    reraise(exc_type, exc_value, tb)
  File "/opt/virtualenvs/python3/lib/python3.8/site-packages/flask/_compat.py", line 39, in reraise
    raise value
  File "/opt/virtualenvs/python3/lib/python3.8/site-packages/flask/app.py", line 1950, in full_dispatch_request
    rv = self.dispatch_request()
  File "/opt/virtualenvs/python3/lib/python3.8/site-packages/flask/app.py", line 1936, in dispatch_request
    return self.view_functions[rule.endpoint](**req.view_args)
  File "/home/runner/ben-ben-spider/app.py", line 76, in main
    return render_template('zhuye.html', v=v, b=b.all(), form=form)
  File "/opt/virtualenvs/python3/lib/python3.8/site-packages/flask/templating.py", line 137, in render_template
    return _render(
  File "/opt/virtualenvs/python3/lib/python3.8/site-packages/flask/templating.py", line 120, in _render
    rv = template.render(context)
  File "/opt/virtualenvs/python3/lib/python3.8/site-packages/jinja2/environment.py", line 1090, in render
    self.environment.handle_exception()
  File "/opt/virtualenvs/python3/lib/python3.8/site-packages/jinja2/environment.py", line 832, in handle_exception
    reraise(*rewrite_traceback_stack(source=source))
  File "/opt/virtualenvs/python3/lib/python3.8/site-packages/jinja2/_compat.py", line 28, in reraise
    raise value.with_traceback(tb)
  File "/home/runner/ben-ben-spider/templates/zhuye.html", line 2, in top-level template code
    {% from 'bootstrap/form.html' import render_form_row,render_field %}
  File "/opt/virtualenvs/python3/lib/python3.8/site-packages/flask/templating.py", line 60, in get_source
    return self._get_source_fast(environment, template)
  File "/opt/virtualenvs/python3/lib/python3.8/site-packages/flask/templating.py", line 89, in _get_source_fast
    raise TemplateNotFound(template)
jinja2.exceptions.TemplateNotFound: bootstrap/form.html
[2021-02-01 03:31:22,411] ERROR in app: Exception on / [GET]
Traceback (most recent call last):
  File "/opt/virtualenvs/python3/lib/python3.8/site-packages/flask/app.py", line 2447, in wsgi_app
    response = self.full_dispatch_request()
  File "/opt/virtualenvs/python3/lib/python3.8/site-packages/flask/app.py", line 1952, in full_dispatch_request
    rv = self.handle_user_exception(e)
  File "/opt/virtualenvs/python3/lib/python3.8/site-packages/flask/app.py", line 1821, in handle_user_exception
    reraise(exc_type, exc_value, tb)
  File "/opt/virtualenvs/python3/lib/python3.8/site-packages/flask/_compat.py", line 39, in reraise
    raise value
  File "/opt/virtualenvs/python3/lib/python3.8/site-packages/flask/app.py", line 1950, in full_dispatch_request
    rv = self.dispatch_request()
  File "/opt/virtualenvs/python3/lib/python3.8/site-packages/flask/app.py", line 1936, in dispatch_request
    return self.view_functions[rule.endpoint](**req.view_args)
  File "/home/runner/ben-ben-spider/app.py", line 76, in main
    return render_template('zhuye.html', v=v, b=b.all(), form=form)
  File "/opt/virtualenvs/python3/lib/python3.8/site-packages/flask/templating.py", line 137, in render_template
    return _render(
  File "/opt/virtualenvs/python3/lib/python3.8/site-packages/flask/templating.py", line 120, in _render
    rv = template.render(context)
  File "/opt/virtualenvs/python3/lib/python3.8/site-packages/jinja2/environment.py", line 1090, in render
    self.environment.handle_exception()
  File "/opt/virtualenvs/python3/lib/python3.8/site-packages/jinja2/environment.py", line 832, in handle_exception
    reraise(*rewrite_traceback_stack(source=source))
  File "/opt/virtualenvs/python3/lib/python3.8/site-packages/jinja2/_compat.py", line 28, in reraise
    raise value.with_traceback(tb)
  File "/home/runner/ben-ben-spider/templates/zhuye.html", line 2, in top-level template code
    {% from 'bootstrap/form.html' import render_form_row,render_field %}
  File "/opt/virtualenvs/python3/lib/python3.8/site-packages/flask/templating.py", line 60, in get_source
    return self._get_source_fast(environment, template)
  File "/opt/virtualenvs/python3/lib/python3.8/site-packages/flask/templating.py", line 89, in _get_source_fast
    raise TemplateNotFound(template)
jinja2.exceptions.TemplateNotFound: bootstrap/form.html
[2021-02-01 03:31:23,408] ERROR in app: Exception on / [GET]
Traceback (most recent call last):
  File "/opt/virtualenvs/python3/lib/python3.8/site-packages/flask/app.py", line 2447, in wsgi_app
    response = self.full_dispatch_request()
  File "/opt/virtualenvs/python3/lib/python3.8/site-packages/flask/app.py", line 1952, in full_dispatch_request
    rv = self.handle_user_exception(e)
  File "/opt/virtualenvs/python3/lib/python3.8/site-packages/flask/app.py", line 1821, in handle_user_exception
    reraise(exc_type, exc_value, tb)
  File "/opt/virtualenvs/python3/lib/python3.8/site-packages/flask/_compat.py", line 39, in reraise
    raise value
  File "/opt/virtualenvs/python3/lib/python3.8/site-packages/flask/app.py", line 1950, in full_dispatch_request
    rv = self.dispatch_request()
  File "/opt/virtualenvs/python3/lib/python3.8/site-packages/flask/app.py", line 1936, in dispatch_request
    return self.view_functions[rule.endpoint](**req.view_args)
  File "/home/runner/ben-ben-spider/app.py", line 76, in main
    return render_template('zhuye.html', v=v, b=b.all(), form=form)
  File "/opt/virtualenvs/python3/lib/python3.8/site-packages/flask/templating.py", line 137, in render_template
    return _render(
  File "/opt/virtualenvs/python3/lib/python3.8/site-packages/flask/templating.py", line 120, in _render
    rv = template.render(context)
  File "/opt/virtualenvs/python3/lib/python3.8/site-packages/jinja2/environment.py", line 1090, in render
    self.environment.handle_exception()
  File "/opt/virtualenvs/python3/lib/python3.8/site-packages/jinja2/environment.py", line 832, in handle_exception
    reraise(*rewrite_traceback_stack(source=source))
  File "/opt/virtualenvs/python3/lib/python3.8/site-packages/jinja2/_compat.py", line 28, in reraise
    raise value.with_traceback(tb)
  File "/home/runner/ben-ben-spider/templates/zhuye.html", line 2, in top-level template code
    {% from 'bootstrap/form.html' import render_form_row,render_field %}
  File "/opt/virtualenvs/python3/lib/python3.8/site-packages/flask/templating.py", line 60, in get_source
    return self._get_source_fast(environment, template)
  File "/opt/virtualenvs/python3/lib/python3.8/site-packages/flask/templating.py", line 89, in _get_source_fast
    raise TemplateNotFound(template)
jinja2.exceptions.TemplateNotFound: bootstrap/form.html
[2021-02-01 03:31:51 +0000] [235] [INFO] Handling signal: int
[2021-02-01 03:31:51 +0000] [237] [INFO] Worker exiting (pid: 237)
[2021-02-01 03:31:51 +0000] [240] [INFO] Worker exiting (pid: 240)
[2021-02-01 03:31:51 +0000] [238] [INFO] Worker exiting (pid: 238)
[2021-02-01 03:31:51 +0000] [239] [INFO] Worker exiting (pid: 239)
[2021-02-01 03:31:53 +0000] [235] [INFO] Shutting down: Master
[2021-02-01 03:32:25 +0000] [263] [INFO] Starting gunicorn 20.0.4
[2021-02-01 03:32:25 +0000] [263] [INFO] Listening at: http://0.0.0.0:8080 (263)
[2021-02-01 03:32:25 +0000] [263] [INFO] Using worker: gevent
[2021-02-01 03:32:25 +0000] [265] [INFO] Booting worker with pid: 265
[2021-02-01 03:32:25 +0000] [266] [INFO] Booting worker with pid: 266
[2021-02-01 03:32:25 +0000] [267] [INFO] Booting worker with pid: 267
[2021-02-01 03:32:25 +0000] [268] [INFO] Booting worker with pid: 268
[2021-02-01 03:33:28 +0000] [263] [INFO] Handling signal: int
[2021-02-01 03:33:28 +0000] [266] [INFO] Worker exiting (pid: 266)
[2021-02-01 03:33:28 +0000] [268] [INFO] Worker exiting (pid: 268)
[2021-02-01 03:33:28 +0000] [267] [INFO] Worker exiting (pid: 267)
[2021-02-01 03:33:28 +0000] [265] [INFO] Worker exiting (pid: 265)
[2021-02-01 03:33:30 +0000] [263] [INFO] Shutting down: Master
[2021-02-01 03:34:01 +0000] [292] [INFO] Starting gunicorn 20.0.4
[2021-02-01 03:34:01 +0000] [292] [INFO] Listening at: http://0.0.0.0:8080 (292)
[2021-02-01 03:34:01 +0000] [292] [INFO] Using worker: gevent
[2021-02-01 03:34:01 +0000] [294] [INFO] Booting worker with pid: 294
[2021-02-01 03:34:01 +0000] [295] [INFO] Booting worker with pid: 295
[2021-02-01 03:34:01 +0000] [296] [INFO] Booting worker with pid: 296
[2021-02-01 03:34:01 +0000] [297] [INFO] Booting worker with pid: 297
[2021-02-01 03:45:04,536] ERROR in app: Exception on /api/checkbenben [GET]
Traceback (most recent call last):
  File "/opt/virtualenvs/python3/lib/python3.8/site-packages/urllib3/connection.py", line 169, in _new_conn
    conn = connection.create_connection(
  File "/opt/virtualenvs/python3/lib/python3.8/site-packages/urllib3/util/connection.py", line 96, in create_connection
    raise err
  File "/opt/virtualenvs/python3/lib/python3.8/site-packages/urllib3/util/connection.py", line 86, in create_connection
    sock.connect(sa)
  File "/opt/virtualenvs/python3/lib/python3.8/site-packages/gevent/_socketcommon.py", line 607, in connect
    raise _SocketError(err, strerror(err))
TimeoutError: [Errno 110] Connection timed out

During handling of the above exception, another exception occurred:

Traceback (most recent call last):
  File "/opt/virtualenvs/python3/lib/python3.8/site-packages/urllib3/connectionpool.py", line 699, in urlopen
    httplib_response = self._make_request(
  File "/opt/virtualenvs/python3/lib/python3.8/site-packages/urllib3/connectionpool.py", line 382, in _make_request
    self._validate_conn(conn)
  File "/opt/virtualenvs/python3/lib/python3.8/site-packages/urllib3/connectionpool.py", line 1010, in _validate_conn
    conn.connect()
  File "/opt/virtualenvs/python3/lib/python3.8/site-packages/urllib3/connection.py", line 353, in connect
    conn = self._new_conn()
  File "/opt/virtualenvs/python3/lib/python3.8/site-packages/urllib3/connection.py", line 181, in _new_conn
    raise NewConnectionError(
urllib3.exceptions.NewConnectionError: <urllib3.connection.HTTPSConnection object at 0x7f8fc72f67f0>: Failed to establish a new connection: [Errno 110] Connection timed out

During handling of the above exception, another exception occurred:

Traceback (most recent call last):
  File "/opt/virtualenvs/python3/lib/python3.8/site-packages/requests/adapters.py", line 439, in send
    resp = conn.urlopen(
  File "/opt/virtualenvs/python3/lib/python3.8/site-packages/urllib3/connectionpool.py", line 755, in urlopen
    retries = retries.increment(
  File "/opt/virtualenvs/python3/lib/python3.8/site-packages/urllib3/util/retry.py", line 573, in increment
    raise MaxRetryError(_pool, url, error or ResponseError(cause))
urllib3.exceptions.MaxRetryError: HTTPSConnectionPool(host='www.luogu.com.cn', port=443): Max retries exceeded with url: /api/feed/list?user=122461 (Caused by NewConnectionError('<urllib3.connection.HTTPSConnection object at 0x7f8fc72f67f0>: Failed to establish a new connection: [Errno 110] Connection timed out'))

During handling of the above exception, another exception occurred:

Traceback (most recent call last):
  File "/opt/virtualenvs/python3/lib/python3.8/site-packages/flask/app.py", line 2447, in wsgi_app
    response = self.full_dispatch_request()
  File "/opt/virtualenvs/python3/lib/python3.8/site-packages/flask/app.py", line 1952, in full_dispatch_request
    rv = self.handle_user_exception(e)
  File "/opt/virtualenvs/python3/lib/python3.8/site-packages/flask/app.py", line 1821, in handle_user_exception
    reraise(exc_type, exc_value, tb)
  File "/opt/virtualenvs/python3/lib/python3.8/site-packages/flask/_compat.py", line 39, in reraise
    raise value
  File "/opt/virtualenvs/python3/lib/python3.8/site-packages/flask/app.py", line 1950, in full_dispatch_request
    rv = self.dispatch_request()
  File "/opt/virtualenvs/python3/lib/python3.8/site-packages/flask/app.py", line 1936, in dispatch_request
    return self.view_functions[rule.endpoint](**req.view_args)
  File "/home/runner/ben-ben-spider/app.py", line 286, in api_checkbenben
    benbens = requests.get('https://www.luogu.com.cn/api/feed/list?user={}'.format(uid),headers=headers).json()
  File "/opt/virtualenvs/python3/lib/python3.8/site-packages/requests/api.py", line 76, in get
    return request('get', url, params=params, **kwargs)
  File "/opt/virtualenvs/python3/lib/python3.8/site-packages/requests/api.py", line 61, in request
    return session.request(method=method, url=url, **kwargs)
  File "/opt/virtualenvs/python3/lib/python3.8/site-packages/requests/sessions.py", line 542, in request
    resp = self.send(prep, **send_kwargs)
  File "/opt/virtualenvs/python3/lib/python3.8/site-packages/requests/sessions.py", line 655, in send
    r = adapter.send(request, **kwargs)
  File "/opt/virtualenvs/python3/lib/python3.8/site-packages/requests/adapters.py", line 516, in send
    raise ConnectionError(e, request=request)
requests.exceptions.ConnectionError: HTTPSConnectionPool(host='www.luogu.com.cn', port=443): Max retries exceeded with url: /api/feed/list?user=122461 (Caused by NewConnectionError('<urllib3.connection.HTTPSConnection object at 0x7f8fc72f67f0>: Failed to establish a new connection: [Errno 110] Connection timed out'))
[2021-02-01 04:45:16 +0000] [17192] [INFO] Starting gunicorn 20.0.4
[2021-02-01 04:45:16 +0000] [17192] [INFO] Listening at: http://0.0.0.0:8080 (17192)
[2021-02-01 04:45:16 +0000] [17192] [INFO] Using worker: gevent
[2021-02-01 04:45:16 +0000] [17194] [INFO] Booting worker with pid: 17194
[2021-02-01 04:45:16 +0000] [17195] [INFO] Booting worker with pid: 17195
[2021-02-01 04:45:16 +0000] [17196] [INFO] Booting worker with pid: 17196
[2021-02-01 04:45:16 +0000] [17197] [INFO] Booting worker with pid: 17197
[2021-02-01 05:14:36 +0000] [526] [INFO] Starting gunicorn 20.0.4
[2021-02-01 05:14:36 +0000] [526] [INFO] Listening at: http://0.0.0.0:8080 (526)
[2021-02-01 05:14:36 +0000] [526] [INFO] Using worker: gevent
[2021-02-01 05:14:36 +0000] [528] [INFO] Booting worker with pid: 528
[2021-02-01 05:14:36 +0000] [529] [INFO] Booting worker with pid: 529
[2021-02-01 05:14:36 +0000] [530] [INFO] Booting worker with pid: 530
[2021-02-01 05:14:36 +0000] [531] [INFO] Booting worker with pid: 531
[2021-02-01 05:56:16 +0000] [1016] [INFO] Starting gunicorn 20.0.4
[2021-02-01 05:56:16 +0000] [1016] [INFO] Listening at: http://0.0.0.0:8080 (1016)
[2021-02-01 05:56:16 +0000] [1016] [INFO] Using worker: gevent
[2021-02-01 05:56:16 +0000] [1026] [INFO] Booting worker with pid: 1026
[2021-02-01 05:56:16 +0000] [1027] [INFO] Booting worker with pid: 1027
[2021-02-01 05:56:16 +0000] [1028] [INFO] Booting worker with pid: 1028
[2021-02-01 05:56:16 +0000] [1029] [INFO] Booting worker with pid: 1029
[2021-02-01 05:56:29 +0000] [1016] [INFO] Handling signal: term
[2021-02-01 05:56:29 +0000] [1016] [INFO] Shutting down: Master
